2019-12-18 08:56:24,944 INFO: Scatterplot startup [in /Users/jboucas/flask_dashboard/app/__init__.py:45]
2019-12-18 08:56:32,743 ERROR: Exception on / [GET] [in /Users/jboucas/flask_dashboard/venv/lib/python3.7/site-packages/flask/app.py:1891]
Traceback (most recent call last):
  File "/Users/jboucas/flask_dashboard/venv/lib/python3.7/site-packages/flask/app.py", line 2446, in wsgi_app
    response = self.full_dispatch_request()
  File "/Users/jboucas/flask_dashboard/venv/lib/python3.7/site-packages/flask/app.py", line 1951, in full_dispatch_request
    rv = self.handle_user_exception(e)
  File "/Users/jboucas/flask_dashboard/venv/lib/python3.7/site-packages/flask/app.py", line 1820, in handle_user_exception
    reraise(exc_type, exc_value, tb)
  File "/Users/jboucas/flask_dashboard/venv/lib/python3.7/site-packages/flask/_compat.py", line 39, in reraise
    raise value
  File "/Users/jboucas/flask_dashboard/venv/lib/python3.7/site-packages/flask/app.py", line 1949, in full_dispatch_request
    rv = self.dispatch_request()
  File "/Users/jboucas/flask_dashboard/venv/lib/python3.7/site-packages/flask/app.py", line 1935, in dispatch_request
    return self.view_functions[rule.endpoint](**req.view_args)
  File "/Users/jboucas/flask_dashboard/venv/lib/python3.7/site-packages/flask_login/utils.py", line 261, in decorated_view
    return func(*args, **kwargs)
  File "/Users/jboucas/flask_dashboard/app/routes.py", line 177, in index
    maxHeightSideBar=int(float(session["width"])*0.9)
  File "/Users/jboucas/flask_dashboard/venv/lib/python3.7/site-packages/werkzeug/local.py", line 378, in <lambda>
    __getitem__ = lambda x, i: x._get_current_object()[i]
KeyError: 'width'
2019-12-18 08:58:44,982 INFO: Scatterplot startup [in /Users/jboucas/flask_dashboard/app/__init__.py:45]
2019-12-18 09:00:03,929 INFO: Scatterplot startup [in /Users/jboucas/flask_dashboard/app/__init__.py:45]
2019-12-18 09:00:21,476 INFO: Scatterplot startup [in /Users/jboucas/flask_dashboard/app/__init__.py:45]
2019-12-18 09:00:35,799 INFO: Scatterplot startup [in /Users/jboucas/flask_dashboard/app/__init__.py:45]
2019-12-18 09:00:50,883 INFO: Scatterplot startup [in /Users/jboucas/flask_dashboard/app/__init__.py:45]
2019-12-18 09:01:18,342 INFO: Scatterplot startup [in /Users/jboucas/flask_dashboard/app/__init__.py:45]
2019-12-18 09:10:19,095 INFO: Scatterplot startup [in /Users/jboucas/flask_dashboard/app/__init__.py:45]
2019-12-18 09:11:58,823 INFO: Scatterplot startup [in /Users/jboucas/flask_dashboard/app/__init__.py:45]
2019-12-18 09:12:24,327 INFO: Scatterplot startup [in /Users/jboucas/flask_dashboard/app/__init__.py:45]
2019-12-18 09:13:50,420 INFO: Scatterplot startup [in /Users/jboucas/flask_dashboard/app/__init__.py:45]
2019-12-18 09:14:04,946 ERROR: Exception on /index [POST] [in /Users/jboucas/flask_dashboard/venv/lib/python3.7/site-packages/flask/app.py:1891]
Traceback (most recent call last):
  File "/Users/jboucas/flask_dashboard/venv/lib/python3.7/site-packages/flask/app.py", line 2446, in wsgi_app
    response = self.full_dispatch_request()
  File "/Users/jboucas/flask_dashboard/venv/lib/python3.7/site-packages/flask/app.py", line 1951, in full_dispatch_request
    rv = self.handle_user_exception(e)
  File "/Users/jboucas/flask_dashboard/venv/lib/python3.7/site-packages/flask/app.py", line 1820, in handle_user_exception
    reraise(exc_type, exc_value, tb)
  File "/Users/jboucas/flask_dashboard/venv/lib/python3.7/site-packages/flask/_compat.py", line 39, in reraise
    raise value
  File "/Users/jboucas/flask_dashboard/venv/lib/python3.7/site-packages/flask/app.py", line 1949, in full_dispatch_request
    rv = self.dispatch_request()
  File "/Users/jboucas/flask_dashboard/venv/lib/python3.7/site-packages/flask/app.py", line 1935, in dispatch_request
    return self.view_functions[rule.endpoint](**req.view_args)
  File "/Users/jboucas/flask_dashboard/venv/lib/python3.7/site-packages/flask_login/utils.py", line 261, in decorated_view
    return func(*args, **kwargs)
  File "/Users/jboucas/flask_dashboard/app/routes.py", line 250, in index
    df=pd.read_json(session["df"])
  File "/Users/jboucas/flask_dashboard/venv/lib/python3.7/site-packages/werkzeug/local.py", line 378, in <lambda>
    __getitem__ = lambda x, i: x._get_current_object()[i]
KeyError: 'df'
2019-12-18 09:14:26,284 ERROR: Exception on /index [POST] [in /Users/jboucas/flask_dashboard/venv/lib/python3.7/site-packages/flask/app.py:1891]
Traceback (most recent call last):
  File "/Users/jboucas/flask_dashboard/venv/lib/python3.7/site-packages/flask/app.py", line 2446, in wsgi_app
    response = self.full_dispatch_request()
  File "/Users/jboucas/flask_dashboard/venv/lib/python3.7/site-packages/flask/app.py", line 1951, in full_dispatch_request
    rv = self.handle_user_exception(e)
  File "/Users/jboucas/flask_dashboard/venv/lib/python3.7/site-packages/flask/app.py", line 1820, in handle_user_exception
    reraise(exc_type, exc_value, tb)
  File "/Users/jboucas/flask_dashboard/venv/lib/python3.7/site-packages/flask/_compat.py", line 39, in reraise
    raise value
  File "/Users/jboucas/flask_dashboard/venv/lib/python3.7/site-packages/flask/app.py", line 1949, in full_dispatch_request
    rv = self.dispatch_request()
  File "/Users/jboucas/flask_dashboard/venv/lib/python3.7/site-packages/flask/app.py", line 1935, in dispatch_request
    return self.view_functions[rule.endpoint](**req.view_args)
  File "/Users/jboucas/flask_dashboard/venv/lib/python3.7/site-packages/flask_login/utils.py", line 261, in decorated_view
    return func(*args, **kwargs)
  File "/Users/jboucas/flask_dashboard/app/routes.py", line 182, in index
    session_=json.load(inputsessionfile)
  File "/Library/Frameworks/Python.framework/Versions/3.7/lib/python3.7/json/__init__.py", line 296, in load
    parse_constant=parse_constant, object_pairs_hook=object_pairs_hook, **kw)
  File "/Library/Frameworks/Python.framework/Versions/3.7/lib/python3.7/json/__init__.py", line 343, in loads
    s = s.decode(detect_encoding(s), 'surrogatepass')
UnicodeDecodeError: 'utf-8' codec can't decode bytes in position 15-16: invalid continuation byte
2019-12-18 09:15:47,908 INFO: Scatterplot startup [in /Users/jboucas/flask_dashboard/app/__init__.py:45]
2019-12-18 09:15:53,996 ERROR: Exception on /index [POST] [in /Users/jboucas/flask_dashboard/venv/lib/python3.7/site-packages/flask/app.py:1891]
Traceback (most recent call last):
  File "/Users/jboucas/flask_dashboard/venv/lib/python3.7/site-packages/pandas/core/indexes/base.py", line 2897, in get_loc
    return self._engine.get_loc(key)
  File "pandas/_libs/index.pyx", line 107, in pandas._libs.index.IndexEngine.get_loc
  File "pandas/_libs/index.pyx", line 131, in pandas._libs.index.IndexEngine.get_loc
  File "pandas/_libs/hashtable_class_helper.pxi", line 1607, in pandas._libs.hashtable.PyObjectHashTable.get_item
  File "pandas/_libs/hashtable_class_helper.pxi", line 1614, in pandas._libs.hashtable.PyObjectHashTable.get_item
KeyError: None

During handling of the above exception, another exception occurred:

Traceback (most recent call last):
  File "/Users/jboucas/flask_dashboard/venv/lib/python3.7/site-packages/flask/app.py", line 2446, in wsgi_app
    response = self.full_dispatch_request()
  File "/Users/jboucas/flask_dashboard/venv/lib/python3.7/site-packages/flask/app.py", line 1951, in full_dispatch_request
    rv = self.handle_user_exception(e)
  File "/Users/jboucas/flask_dashboard/venv/lib/python3.7/site-packages/flask/app.py", line 1820, in handle_user_exception
    reraise(exc_type, exc_value, tb)
  File "/Users/jboucas/flask_dashboard/venv/lib/python3.7/site-packages/flask/_compat.py", line 39, in reraise
    raise value
  File "/Users/jboucas/flask_dashboard/venv/lib/python3.7/site-packages/flask/app.py", line 1949, in full_dispatch_request
    rv = self.dispatch_request()
  File "/Users/jboucas/flask_dashboard/venv/lib/python3.7/site-packages/flask/app.py", line 1935, in dispatch_request
    return self.view_functions[rule.endpoint](**req.view_args)
  File "/Users/jboucas/flask_dashboard/venv/lib/python3.7/site-packages/flask_login/utils.py", line 261, in decorated_view
    return func(*args, **kwargs)
  File "/Users/jboucas/flask_dashboard/app/routes.py", line 253, in index
    fig=make_figure(df,plot_arguments)
  File "/Users/jboucas/flask_dashboard/app/routes.py", line 41, in make_figure
    x=df[pa["xvals"]].tolist()
  File "/Users/jboucas/flask_dashboard/venv/lib/python3.7/site-packages/pandas/core/frame.py", line 2995, in __getitem__
    indexer = self.columns.get_loc(key)
  File "/Users/jboucas/flask_dashboard/venv/lib/python3.7/site-packages/pandas/core/indexes/base.py", line 2899, in get_loc
    return self._engine.get_loc(self._maybe_cast_indexer(key))
  File "pandas/_libs/index.pyx", line 107, in pandas._libs.index.IndexEngine.get_loc
  File "pandas/_libs/index.pyx", line 131, in pandas._libs.index.IndexEngine.get_loc
  File "pandas/_libs/hashtable_class_helper.pxi", line 1607, in pandas._libs.hashtable.PyObjectHashTable.get_item
  File "pandas/_libs/hashtable_class_helper.pxi", line 1614, in pandas._libs.hashtable.PyObjectHashTable.get_item
KeyError: None
2019-12-18 09:16:47,694 INFO: Scatterplot startup [in /Users/jboucas/flask_dashboard/app/__init__.py:45]
2019-12-18 09:17:49,775 INFO: Scatterplot startup [in /Users/jboucas/flask_dashboard/app/__init__.py:45]
2019-12-18 09:18:24,283 INFO: Scatterplot startup [in /Users/jboucas/flask_dashboard/app/__init__.py:45]
2019-12-18 09:19:08,754 INFO: Scatterplot startup [in /Users/jboucas/flask_dashboard/app/__init__.py:45]
2019-12-18 09:20:25,519 INFO: Scatterplot startup [in /Users/jboucas/flask_dashboard/app/__init__.py:45]
2019-12-18 09:21:01,331 INFO: Scatterplot startup [in /Users/jboucas/flask_dashboard/app/__init__.py:45]
2020-01-28 15:30:57,524 INFO: Scatterplot startup [in /Users/jboucas/flask_dashboard/app/__init__.py:54]
2020-01-28 15:36:48,678 INFO: Scatterplot startup [in /Users/jboucas/flask_dashboard/app/__init__.py:54]
2020-01-28 15:38:49,126 INFO: Scatterplot startup [in /Users/jboucas/flask_dashboard/app/__init__.py:54]
