2019-12-17 02:06:42,862 ERROR: Exception on /index [POST] [in /Users/jboucas/flask_dashboard/venv/lib/python3.7/site-packages/flask/app.py:1891]
Traceback (most recent call last):
  File "/Users/jboucas/flask_dashboard/venv/lib/python3.7/site-packages/pandas/core/indexes/base.py", line 2897, in get_loc
    return self._engine.get_loc(key)
  File "pandas/_libs/index.pyx", line 107, in pandas._libs.index.IndexEngine.get_loc
  File "pandas/_libs/index.pyx", line 131, in pandas._libs.index.IndexEngine.get_loc
  File "pandas/_libs/hashtable_class_helper.pxi", line 1607, in pandas._libs.hashtable.PyObjectHashTable.get_item
  File "pandas/_libs/hashtable_class_helper.pxi", line 1614, in pandas._libs.hashtable.PyObjectHashTable.get_item
KeyError: None

During handling of the above exception, another exception occurred:

Traceback (most recent call last):
  File "/Users/jboucas/flask_dashboard/venv/lib/python3.7/site-packages/flask/app.py", line 2446, in wsgi_app
    response = self.full_dispatch_request()
  File "/Users/jboucas/flask_dashboard/venv/lib/python3.7/site-packages/flask/app.py", line 1951, in full_dispatch_request
    rv = self.handle_user_exception(e)
  File "/Users/jboucas/flask_dashboard/venv/lib/python3.7/site-packages/flask/app.py", line 1820, in handle_user_exception
    reraise(exc_type, exc_value, tb)
  File "/Users/jboucas/flask_dashboard/venv/lib/python3.7/site-packages/flask/_compat.py", line 39, in reraise
    raise value
  File "/Users/jboucas/flask_dashboard/venv/lib/python3.7/site-packages/flask/app.py", line 1949, in full_dispatch_request
    rv = self.dispatch_request()
  File "/Users/jboucas/flask_dashboard/venv/lib/python3.7/site-packages/flask/app.py", line 1935, in dispatch_request
    return self.view_functions[rule.endpoint](**req.view_args)
  File "/Users/jboucas/flask_dashboard/venv/lib/python3.7/site-packages/flask_login/utils.py", line 261, in decorated_view
    return func(*args, **kwargs)
  File "/Users/jboucas/flask_dashboard/app/routes.py", line 242, in index
    fig=make_figure(df,plot_arguments)
  File "/Users/jboucas/flask_dashboard/app/routes.py", line 39, in make_figure
    x=df[pa["xvals"]].tolist()
  File "/Users/jboucas/flask_dashboard/venv/lib/python3.7/site-packages/pandas/core/frame.py", line 2995, in __getitem__
    indexer = self.columns.get_loc(key)
  File "/Users/jboucas/flask_dashboard/venv/lib/python3.7/site-packages/pandas/core/indexes/base.py", line 2899, in get_loc
    return self._engine.get_loc(self._maybe_cast_indexer(key))
  File "pandas/_libs/index.pyx", line 107, in pandas._libs.index.IndexEngine.get_loc
  File "pandas/_libs/index.pyx", line 131, in pandas._libs.index.IndexEngine.get_loc
  File "pandas/_libs/hashtable_class_helper.pxi", line 1607, in pandas._libs.hashtable.PyObjectHashTable.get_item
  File "pandas/_libs/hashtable_class_helper.pxi", line 1614, in pandas._libs.hashtable.PyObjectHashTable.get_item
KeyError: None
2019-12-17 02:07:27,649 INFO: Scatterplot startup [in /Users/jboucas/flask_dashboard/app/__init__.py:45]
2019-12-17 02:10:02,607 INFO: Scatterplot startup [in /Users/jboucas/flask_dashboard/app/__init__.py:45]
2019-12-17 02:11:05,737 INFO: Scatterplot startup [in /Users/jboucas/flask_dashboard/app/__init__.py:45]
2019-12-17 02:12:27,941 INFO: Scatterplot startup [in /Users/jboucas/flask_dashboard/app/__init__.py:45]
2019-12-17 02:14:23,816 INFO: Scatterplot startup [in /Users/jboucas/flask_dashboard/app/__init__.py:45]
2019-12-17 02:16:02,459 INFO: Scatterplot startup [in /Users/jboucas/flask_dashboard/app/__init__.py:45]
2019-12-17 02:20:55,397 ERROR: Exception on /login [POST] [in /Users/jboucas/flask_dashboard/venv/lib/python3.7/site-packages/flask/app.py:1891]
Traceback (most recent call last):
  File "/Users/jboucas/flask_dashboard/venv/lib/python3.7/site-packages/flask/app.py", line 2446, in wsgi_app
    response = self.full_dispatch_request()
  File "/Users/jboucas/flask_dashboard/venv/lib/python3.7/site-packages/flask/app.py", line 1951, in full_dispatch_request
    rv = self.handle_user_exception(e)
  File "/Users/jboucas/flask_dashboard/venv/lib/python3.7/site-packages/flask/app.py", line 1820, in handle_user_exception
    reraise(exc_type, exc_value, tb)
  File "/Users/jboucas/flask_dashboard/venv/lib/python3.7/site-packages/flask/_compat.py", line 39, in reraise
    raise value
  File "/Users/jboucas/flask_dashboard/venv/lib/python3.7/site-packages/flask/app.py", line 1949, in full_dispatch_request
    rv = self.dispatch_request()
  File "/Users/jboucas/flask_dashboard/venv/lib/python3.7/site-packages/flask/app.py", line 1935, in dispatch_request
    return self.view_functions[rule.endpoint](**req.view_args)
  File "/Users/jboucas/flask_dashboard/app/routes.py", line 129, in login
    if not next_page or url_parse(next_page).netloc != '':
NameError: name 'url_parse' is not defined
2019-12-17 02:22:17,219 INFO: Scatterplot startup [in /Users/jboucas/flask_dashboard/app/__init__.py:45]
2019-12-17 02:23:50,635 ERROR: Exception on /login [POST] [in /Users/jboucas/flask_dashboard/venv/lib/python3.7/site-packages/flask/app.py:1891]
Traceback (most recent call last):
  File "/Users/jboucas/flask_dashboard/venv/lib/python3.7/site-packages/flask/app.py", line 2446, in wsgi_app
    response = self.full_dispatch_request()
  File "/Users/jboucas/flask_dashboard/venv/lib/python3.7/site-packages/flask/app.py", line 1951, in full_dispatch_request
    rv = self.handle_user_exception(e)
  File "/Users/jboucas/flask_dashboard/venv/lib/python3.7/site-packages/flask/app.py", line 1820, in handle_user_exception
    reraise(exc_type, exc_value, tb)
  File "/Users/jboucas/flask_dashboard/venv/lib/python3.7/site-packages/flask/_compat.py", line 39, in reraise
    raise value
  File "/Users/jboucas/flask_dashboard/venv/lib/python3.7/site-packages/flask/app.py", line 1949, in full_dispatch_request
    rv = self.dispatch_request()
  File "/Users/jboucas/flask_dashboard/venv/lib/python3.7/site-packages/flask/app.py", line 1935, in dispatch_request
    return self.view_functions[rule.endpoint](**req.view_args)
  File "/Users/jboucas/flask_dashboard/app/routes.py", line 129, in login
    if not next_page or url_parse(next_page).netloc != '':
NameError: name 'url_parse' is not defined
2019-12-17 02:27:50,858 INFO: Scatterplot startup [in /Users/jboucas/flask_dashboard/app/__init__.py:45]
2019-12-17 02:29:27,429 INFO: Scatterplot startup [in /Users/jboucas/flask_dashboard/app/__init__.py:45]
2019-12-17 02:29:34,089 ERROR: Exception on /login [POST] [in /Users/jboucas/flask_dashboard/venv/lib/python3.7/site-packages/flask/app.py:1891]
Traceback (most recent call last):
  File "/Users/jboucas/flask_dashboard/venv/lib/python3.7/site-packages/flask/app.py", line 2446, in wsgi_app
    response = self.full_dispatch_request()
  File "/Users/jboucas/flask_dashboard/venv/lib/python3.7/site-packages/flask/app.py", line 1951, in full_dispatch_request
    rv = self.handle_user_exception(e)
  File "/Users/jboucas/flask_dashboard/venv/lib/python3.7/site-packages/flask/app.py", line 1820, in handle_user_exception
    reraise(exc_type, exc_value, tb)
  File "/Users/jboucas/flask_dashboard/venv/lib/python3.7/site-packages/flask/_compat.py", line 39, in reraise
    raise value
  File "/Users/jboucas/flask_dashboard/venv/lib/python3.7/site-packages/flask/app.py", line 1949, in full_dispatch_request
    rv = self.dispatch_request()
  File "/Users/jboucas/flask_dashboard/venv/lib/python3.7/site-packages/flask/app.py", line 1935, in dispatch_request
    return self.view_functions[rule.endpoint](**req.view_args)
  File "/Users/jboucas/flask_dashboard/app/routes.py", line 129, in login
    if not next_page or url_parse(next_page).netloc != '':
NameError: name 'url_parse' is not defined
